 2018-02-09 07:08:03,723 1 INFO ? odoo.sql_db: Connection to the database failed
odoo-10e | 2018-02-09 07:08:03,726 1 INFO ? werkzeug: 200.83.199.9 - - [09/Feb/2018 07:08:03] "GET /favicon.ico HTTP/1.1" 500 -
odoo-10e | 2018-02-09 07:08:03,733 1 ERROR ? werkzeug: Error on request:
odoo-10e | Traceback (most recent call last):
odoo-10e |   File "/usr/lib/python2.7/dist-packages/werkzeug/serving.py", line 177, in run_wsgi
odoo-10e |     execute(self.server.app)
odoo-10e |   File "/usr/lib/python2.7/dist-packages/werkzeug/serving.py", line 165, in execute
odoo-10e |     application_iter = app(environ, start_response)
odoo-10e |   File "/usr/lib/python2.7/dist-packages/odoo/service/server.py", line 246, in app
odoo-10e |     return self.app(e, s)
odoo-10e |   File "/usr/lib/python2.7/dist-packages/odoo/service/wsgi_server.py", line 186, in application
odoo-10e |     return application_unproxied(environ, start_response)
odoo-10e |   File "/usr/lib/python2.7/dist-packages/odoo/service/wsgi_server.py", line 172, in application_unproxied
odoo-10e |     result = handler(environ, start_response)
odoo-10e |   File "/usr/lib/python2.7/dist-packages/odoo/http.py", line 1308, in __call__
odoo-10e |     return self.dispatch(environ, start_response)
odoo-10e |   File "/usr/lib/python2.7/dist-packages/odoo/http.py", line 1282, in __call__
odoo-10e |     return self.app(environ, start_wrapped)
odoo-10e |   File "/usr/lib/python2.7/dist-packages/werkzeug/wsgi.py", line 588, in __call__
odoo-10e |     return self.app(environ, start_response)
odoo-10e |   File "/usr/lib/python2.7/dist-packages/odoo/http.py", line 1446, in dispatch
odoo-10e |     self.setup_db(httprequest)
odoo-10e |   File "/usr/lib/python2.7/dist-packages/odoo/http.py", line 1368, in setup_db
odoo-10e |     httprequest.session.db = db_monodb(httprequest)
odoo-10e |   File "/usr/lib/python2.7/dist-packages/odoo/http.py", line 1530, in db_monodb
odoo-10e |     dbs = db_list(True, httprequest)
odoo-10e |   File "/usr/lib/python2.7/dist-packages/odoo/http.py", line 1498, in db_list
odoo-10e |     dbs = odoo.service.db.list_dbs(force)
odoo-10e |   File "/usr/lib/python2.7/dist-packages/odoo/service/db.py", line 333, in list_dbs
odoo-10e |     with closing(db.cursor()) as cr:
odoo-10e |   File "/usr/lib/python2.7/dist-packages/odoo/sql_db.py", line 635, in cursor
odoo-10e |     return Cursor(self.__pool, self.dbname, self.dsn, serialized=serialized)
odoo-10e |   File "/usr/lib/python2.7/dist-packages/odoo/sql_db.py", line 177, in __init__
odoo-10e |     self._cnx = pool.borrow(dsn)
odoo-10e |   File "/usr/lib/python2.7/dist-packages/odoo/sql_db.py", line 518, in _locked
odoo-10e |     return fun(self, *args, **kwargs)
odoo-10e |   File "/usr/lib/python2.7/dist-packages/odoo/sql_db.py", line 586, in borrow
odoo-10e |     **connection_info)
odoo-10e |   File "/usr/lib/python2.7/dist-packages/psycopg2/__init__.py", line 164, in connect
odoo-10e |     conn = _connect(dsn, connection_factory=connection_factory, async=async)
odoo-10e | OperationalError: could not connect to server: Connection refused
odoo-10e |      Is the server running on host "50.116.11.91" and accepting
odoo-10e |      TCP/IP connections on port 5432?
